Workbook

Sheet Sheet1
A1: Status | B1: Order Type | C1: Service Type | D1: Contact Person | E1: Contact Number | F1: Contact Email | G1: Company Name | H1: Standardized Company Name | I1: Product Subscribe | J1: Billing Account / Master Account | K1: Account/Root ID UID | L1: Account Name | M1: Account Login Email | N1: Password | O1: Billing Address | P1: Other Account Information | Q1: SRD | R1: Order Receive Date | S1: CxS Complete Date | T1: Service No. | U1: CxS Request No. | V1: TID | W1: OASIS Number | X1: SD Number | Y1: Remark | Z1: PS Job | AA1: T2/ T3 | AB1: Welcome Letter | AC1: By | AD1: Order Form
A2: Completed | D2: Ron Ko | E2: 23038766 | G2: WING FUNG REALTY INVESTMENT LIMITED | H2: =IFERROR(VLOOKUP(G2, Sheet2!$A:$B, 2, FALSE), A2) -> WING FUNG REALTY INVESTMENT LIMITED | I2: AWS (Amazon Web Service) | M2: infrastructure@wfgold.com | N2: 3txj18487i | Q2: 43885 | S2: 43885 | T2: CL554098 | U2: 393444/1-2 | V2: 102318
A3: Completed | D3: Ron Ko | E3: 23038766 | G3: WING FUNG REALTY INVESTMENT LIMITED | H3: =IFERROR(VLOOKUP(G3, Sheet2!$A:$B, 2, FALSE), A3) -> WING FUNG REALTY INVESTMENT LIMITED | I3: Alibaba Cloud | K3: 5794684087356582 | M3: it0001@wfgold.com | Q3: 44092 | S3: 44123 | T3: CL544006 | U3: 149525/1-2 | V3: 102456 | Y3: [19-Oct-2020] Linking is completed. Request to amended SRD to 19-Oct-2020 by Ann. [22-Oct-2020] Checked SRD not update yet. Sent email to Sammy [23-Oct-2020] Sammy confirmed no need to change SRD as no contract boundary. Completed order in CxS with SRD on 19-Oct-20 [28-Apr-2021] Migration request from Zens to B-Data by Thomas [17-Jul-2021] Bdata updaed that migration completed | Z3: N | AA3: 1 | AC3: Ann
A4: Completed | D4: Ron Ko | E4: 23038766 | F4: ronko@wfgold.com | G4: WING FUNG PRECIOUS METALS LIMITED | H4: =IFERROR(VLOOKUP(G4, Sheet2!$A:$B, 2, FALSE), A4) -> WING FUNG PRECIOUS METALS LIMITED | I4: AWS (Amazon Web Service) | J4: infrastructure@wfgold.com | K4: 169239530719 | L4: pm_infra@wfgold.com | M4: pm_infra@wfgold.com | Q4: 44042 | S4: 44042 | T4: CL559730 | U4: RN640134/1-2 | V4: 102432 | Y4: [29-Jul-20] Submitted request to Ingram. Cus accepted. Pending for cloud checkr setup [4-Aug-20] Completed in CxS with completion date on 30-Jul-20 [16-Sep-20] checked no consumption yet [9-Oct-2020] Billing account setup under | AB4: Yes
A5: Completed | D5: Ron Ko | E5: 23038766 | G5: WING FUNG FUTURES LIMITED | H5: =IFERROR(VLOOKUP(G5, Sheet2!$A:$B, 2, FALSE), A5) -> WING FUNG FUTURES LIMITED | I5: AWS (Amazon Web Service) | K5: 974644219856 | M5: fu_infra@wfgold.com | Q5: 44047 | S5: 44047 | T5: CL559699 | U5: 652533/1-2 | V5: 102430 | Y5: [30-Jul-20] Submitted request to Ingram. [31-Jul-20]Cus accepted. Penidng for cloud checkr setup [4-Aug-20] Completed in CxS with completion date on 4-Aug-20 [10-Aug-20] Added in cloudcheckr
A6: Completed | D6: Ron Ko | E6: 23038766 | F6: Customer contact : ronko@wfgold.com | G6: WING FUNG BULLION INVESTMENT LIMITED | H6: =IFERROR(VLOOKUP(G6, Sheet2!$A:$B, 2, FALSE), A6) -> WING FUNG BULLION INVESTMENT LIMITED | I6: AWS (Amazon Web Service) | K6: 875512351873 | M6: Login account : bi_infra@wfgold.com Password : s9r5k5ea8y | P6: Root Login : bi_infra@wfgold.com | Q6: 43902 | S6: 43909 | T6: CL557680 | U6: 795404/1-2 | V6: 102336 | Y6: Customer contact : ronko@wfgold.com 875512351873 Root Login : bi_infra@wfgold.com [19-Mar-2020] Customer accepted invitation on. Case completed in CxS with completion date on 19-Mar-2020 [4-Jun-2020] moved to Ingram Micro on 1-Jun and added into HKT family on 4-Jun.
A7: Completed | D7: Brian Yeung | E7: 22129233 / 60634889 | F7: CUS Email : Brian.C.Yeung@honourprinting.com | G7: UMADX ONLINE (MALAYSIA) SDN. BHD | H7: =IFERROR(VLOOKUP(G7, Sheet2!$A:$B, 2, FALSE), A7) -> UMADX ONLINE (MALAYSIA) SDN. BHD | I7: Microsoft Azure | M7: Tenant ID : umadxonline.onmicrosoft.com | O7: Address: 15/F MAGNET PLACE TOWER 1, 77-81 CONTAINER PORT ROAD, KWAI CHUNG NEW TERRITORIES | Q7: 44055 | S7: 44050 | T7: CL541911 | U7: 503074/1-2 | V7: 102438 | Y7: Address: 15/F MAGNET PLACE TOWER 1, 77-81 CONTAINER PORT ROAD, KWAI CHUNG NEW TERRITORIES CUS Email : Brian.C.Yeung@honourprinting.com [7-Aug-2020] Acc created. Pass logn to sales.Welcome letter sent. Completed in CxS.
A8: Completed | D8: Davy Liu | E8: 28302631 / 90255571 | G8: TYSAN MANAGEMENT LIMITED | H8: =IFERROR(VLOOKUP(G8, Sheet2!$A:$B, 2, FALSE), A8) -> TYSAN MANAGEMENT LIMITED | I8: AWS (Amazon Web Service) | K8: 87697955396 | M8: Root Login : davyliu@tysan.com | Q8: 43977 | S8: 43983 | T8: CL545361 | U8: RN148163/1-2 | V8: 102382 | Y8: [20-May-2020] Submitted request to Ingram. Pending for their reply. [28-May-2020] Customer accepted invitation. Waiting for Ingram to add account into cloud checkr [1-Jun-2020] Cloud Checkr set up completed. Case completed in SRS.
A9: Completed | D9: Kevin Chan | E9: 25962878 / 62888721 | F9: Cus contact: kevinchan@travelsky.com.hk | G9: TRAVELSKY TECHNOLOGY (HONGKONG) LTD. | H9: =IFERROR(VLOOKUP(G9, Sheet2!$A:$B, 2, FALSE), A9) -> TRAVELSKY TECHNOLOGY (HONGKONG) LTD. | I9: Google Cloud Platform (GCP) | M9: Root Login: darasakor@travelsky.com.hk | Q9: 44053 | S9: 44054 | T9: CL540961 | U9: 932200/1-2 | V9: 102442 | Y9: Cus contact: kevinchan@travelsky.com.hk [7-Aug-2020]Billing Account creatd and pendng for customer linking acc to HKT. [11-Aug-20] Customer complete linking to HKT. Complete order in CxS with completion date 11-Aug. Welcome letter sent
A10: Completed | D10: Eddy Fung | E10: 2402 6400 / 91798730 | G10: Techtronic Industries Co. Ltd | H10: =IFERROR(VLOOKUP(G10, Sheet2!$A:$B, 2, FALSE), A10) -> Techtronic Industries Co. Ltd | I10: AWS (Amazon Web Service) | K10: 765879711441 | L10: Techtronic Industries Co. Ltd | M10: Root email: aws.hkt@tti.com.hk | O10: Addr3ess: 28/F, Tower 2, KCC, Kwai Chung, NT | Q10: 43591 | S10: 44298 | T10: CL542277 | U10: 731246/3-4 | V10: 101990 | Y10: Provisioned originally by Ann Li ( @ ecloudvalley ) Addr3ess: 28/F, Tower 2, KCC, Kwai Chung, NT [9-Apr-2021] Consultant Tony request to link up with ingram Micro due to cus accidentally quit ecloudvalley. [ cus didn't migrate to ingram micro at the time of changing vendor ] . Submitted request w/o address to ingram micro due to urgency. [10-Apr-2021] Ingram micro sent invitation to cus and cus accepted. [12-Apr-2021] Pending for usage for issue welcome letter [20-Apr-2021] Checked usage on 12-Apr-2021. Welcom letter sent | Z10: N
A11: Completed | D11: Federick Alex (Admin ) / Kenny Chan (IT) | E11: 27938887 / 26938891 | G11: SOFI SECURITIES LIMITED (SOFI SERVICES ( HONG KONG ) LTD) | H11: =IFERROR(VLOOKUP(G11, Sheet2!$A:$B, 2, FALSE), A11) -> SOFI SECURITIES LIMITED (SOFI SERVICES ( HONG KONG ) LTD) | I11: Alibaba Cloud | K11: 5497093001888295 | Q11: 44027 | S11: 44027 | T11: CL555456 | V11: 102198 | Y11: REMARK: Change register name from 8 securites Ltd to Sofi Services (Hong Kong) ltd ( Change of company name order only ) [21-Sep-2020] completed order in CxS with SRD on 15-Jul-2020
A12: Completed | D12: BEN SZE | E12: 23139152 / 62772626 | G12: PROFIT CHART DEVELOPMENT LIMITED | H12: =IFERROR(VLOOKUP(G12, Sheet2!$A:$B, 2, FALSE), A12) -> PROFIT CHART DEVELOPMENT LIMITED | I12: AWS (Amazon Web Service) | K12: 812560180108 | M12: Root Login: mis@newaykb.com.hk | O12: Address : Flat 801, 8/F, East Ocean Cente, 98 Granvielle Road, Tst | Q12: 44096 | S12: 44097 | T12: CL543893 | U12: 157216/1-2 | V12: 102460 | Y12: Address : Flat 801, 8/F, East Ocean Cente, 98 Granvielle Road, Tst [18-Sep-2020] submitted request to ingram. Pending for ingram reply. [22-Sep-2020] Cus accepted invitation ( Thomas provide screen cap ). Completed order in CxS. Pending for cloud checkr setup [25-Sep-2020] Cloudcheckr setuip completed. | Z12: N
A13: Completed | D13: Jessie Li / Hugo Choi | E13: 9022 5988 / 9357 4353 | F13: =F15 -> 0 | G13: ORANGE DATA LIMITED (Chnaged ASCENTAS CAPITAL MANAGEMENT LIMITED) | H13: =IFERROR(VLOOKUP(G13, Sheet2!$A:$B, 2, FALSE), A13) -> ASCENTAS CAPITAL MANAGEMENT LIMITED | I13: Alibaba Cloud | K13: 5864600931668619 | M13: Link Email : infra.consult@pgpg.la | Q13: 44119 | S13: 44117 | T13: CL544854 | U13: 499248/1-2 | V13: 102472 | Y13: Provisioned by Ann Li [12-Nov-20] Ann updated that the case was completed on 13-Oct. Completed in CxS with completion date on 13-Oct-20. [28-Apr-2021] Migration request from Zens to B-Data by Thomas [2-Jun-2021] Migraion completed on 2-Jun-2021. | Z13: N
A14: Completed | D14: Cheng Ping Wai | E14: 27938376 / 98522884 | F14: pw.cheng@leverstyle.com | G14: LEVER SHIRT LIMITED | H14: =IFERROR(VLOOKUP(G14, Sheet2!$A:$B, 2, FALSE), A14) -> LEVER SHIRT LIMITED | I14: Microsoft Azure | Q14: 43830 | S14: 43909 | T14: CL547226 | U14: 954467/1-2 | V14: 102340 | Y14: backdate order. [19-Mar-2020] Peter replied that the service has been provisioned. Case completedin CxS with completion date on 19-Mar-2020.
A15: Completed | D15: Dick Tong | E15: 28999467 / 90256906 | G15: LEIGH & ORANGE LTD | H15: =IFERROR(VLOOKUP(G15, Sheet2!$A:$B, 2, FALSE), A15) -> LEIGH & ORANGE LTD | I15: AWS (Amazon Web Service) | K15: 320298981373 | M15: Login account : itadmin@leighorange.com Password : pq2s5gy0jf | Q15: 43852 | S15: 43892 | T15: CL548876 | U15: 663268/1-2 | V15: 102302 | Y15: AWS Account ID: 320298981373 Root Login : itadmin@leighorange.com [2-Mar-2020] completed in CxS.
A16: Completed | G16: LEGAL AID DEPT | H16: =IFERROR(VLOOKUP(G16, Sheet2!$A:$B, 2, FALSE), A16) -> LEGAL AID DEPT | I16: Google Cloud Platform (GCP) | Q16: 43741 | T16: CL552465 | U16: 919068/1-2 | V16: 102190 | Y16: Revised SRD from 3-Oct to 27-Sep by ordering team (SP handle by product team)
A17: Completed | D17: Randy Mark | E17: 39745607 / 60110033 | F17: Cutomer email: rmark@kbquest.com | G17: KBQUEST HONG KONG LIMITED OGCIO | H17: =IFERROR(VLOOKUP(G17, Sheet2!$A:$B, 2, FALSE), A17) -> KBQUEST HONG KONG LIMITED OGCIO | I17: Microsoft Azure | M17: Tenant ID : ogciosmartlampost.onmicrosoft.com | Q17: 44047 | S17: 44047 | T17: CL559571 | U17: 048802/1-2 | V17: 102428 | Y17: Cutomer email: rmark@kbquest.com [31-Jul-20] Product Peter replied that no need to provision for this customer as they will take over the existing tenant of OGCIO (Customer name in CSP : Office of the Government Chief Information Officer) Remark: Call in on behalf of OGCIO [4-Aug-20] Completed in CxS with completion date on 4-Aug
A18: Completed | D18: Tony Cheng / Ringo Lau | E18: 27820875/ 27827533 | F18: ringolau@takhk.com | G18: ITAK (INTERNATIONAL) LIMITED | H18: =IFERROR(VLOOKUP(G18, Sheet2!$A:$B, 2, FALSE), A18) -> ITAK (INTERNATIONAL) LIMITED | I18: Microsoft Azure | Q18: 43930 | S18: 43930 | T18: CL541269 | U18: 671011/1-2 | V18: 102354 | Y18: [7-Apr-2020] Peter has provisioned the service for customer.
A19: Completed | D19: Mr Brian Yeung | E19: 22129233 / 60634889 | F19: CUS Email : Brian.C.Yeung@honourprinting.com | G19: HONOUR MAILING AND PRINTING LTD | H19: =IFERROR(VLOOKUP(G19, Sheet2!$A:$B, 2, FALSE), A19) -> HONOUR MAILING AND PRINTING LTD | M19: Tenant ID : umadxonline.onmicrosoft.com | O19: Address: 15/F MAGNET PLACE TOWER 1, 77-81 CONTAINER PORT ROAD, KWAI CHUNG NEW TERRITORIES | Q19: 44061 | S19: 44109 | T19: CL550279 | U19: 78673/1-2 | V19: 102446 | Y19: Address: 15/F MAGNET PLACE TOWER 1, 77-81 CONTAINER PORT ROAD, KWAI CHUNG NEW TERRITORIES CUS Email : Brian.C.Yeung@honourprinting.com PS job order ( refer to CL541911 ) [7-Sep-2020] Sent email to Peter for update [16-Sep-2020] sent email for update again [5-Oct-2020] AM Ceilia confrimed all job completed. completed CxS order with completiondate on 5-Oct-2020. | Z19: Y
A20: Completed | D20: Albert Cheng | E20: 2260 3499 / 9681 3499 | F20: Contact Email : albert.cheng@haesl.com | G20: HONG KONG AERO ENGINE SERVICES LTD | H20: =IFERROR(VLOOKUP(G20, Sheet2!$A:$B, 2, FALSE), A20) -> HONG KONG AERO ENGINE SERVICES LTD | I20: AWS (Amazon Web Service) | K20: 146909753979 | M20: Root Login :tech.team@haesl.com | Q20: 44021 | S20: 44025 | T20: CL550611 | U20: RN492408/1-2 | V20: 102408 | Y20: Contact Email : albert.cheng@haesl.com [7-Jul-2020] Submitted request to Ingram. Pending for their reply. [8-Jul-2020] Customer accepted invitation and completed orderin CxS. [8-Jul-2020] pending for ingram to consolidate billing to cloud checkr [13-Jul-2020] Cloud checkr setup completed. [13-Aug-2020] Add once off charge order RN089097/1-2 for PS job
A21: Completed | D21: Albert Cheng | E21: 2260 3499 / 9681 3499 | G21: HONG KONG AERO ENGINE SERVICES LTD | H21: =IFERROR(VLOOKUP(G21, Sheet2!$A:$B, 2, FALSE), A21) -> HONG KONG AERO ENGINE SERVICES LTD | Q21: 44056 | S21: 44055 | T21: CL550611 | U21: RN089097/1-2 | V21: 102408 | Y21: Remark: PS job order of RN492408/1-2 [7-Sep-2020] Updated from PS team Lok that PS job was completed on 15-Jul-2020. Case completed in CxS with completion date on 12-Aug-2020 | Z21: Y
A22: Completed | D22: Roger Ng | F22: roger.kw.ng@pccw.com | G22: HKT Limited ( HKT Wireless Business ) | H22: =IFERROR(VLOOKUP(G22, Sheet2!$A:$B, 2, FALSE), A22) -> HKT Limited ( HKT Wireless Business ) | I22: AWS (Amazon Web Service) | M22: 463675202152 Root Login NA | S22: 44021 | T22: NA | U22: NA | Y22: Remark : No Order issue Customer Email : roger.kw.ng@pccw.com [9-Jul-2020] Added user to accoutns families ( group & user set up by Thomas )
A23: Completed | D23: Stanley Chan ( HKT ) | E23: 2883 2922 / 2883 2922 | G23: HKT Green Mini Bus | H23: =IFERROR(VLOOKUP(G23, Sheet2!$A:$B, 2, FALSE), A23) -> HKT Green Mini Bus | I23: AWS (Amazon Web Service) | K23: 955279921091 | L23: Csutomer email: sunnymak@firstbullion.com | M23: Root ID: hkt-gmb@hkt-cloud.com PW: hkt-gmbcus004 | Q23: 44116 | S23: 44113 | T23: CL544571 | U23: 658593/1-2 | V23: 102473 | Y23: Remark HKT owned account Contact Person : Stanley.yk.chan@pccw.com [8-Oct-20] HKT email account & AWS account created. [9-Oct-20] Sent request to ingram. Pending for ingram reply. [9-Oct-20] Stanley accept the invitation and welcome letter sent.Completed in CxS with completion date on 9-OCt-2020 [16-Oct-20] Cloudcheckr setup completed | Z23: N
A24: Cancelled | D24: Sunny Mak | E24: 21146105/ 92538264 | F24: Csutomer email: sunnymak@firstbullion.com | G24: FIRST ASIA MERCHANTS BULLION LIMITED | H24: =IFERROR(VLOOKUP(G24, Sheet2!$A:$B, 2, FALSE), A24) -> FIRST ASIA MERCHANTS BULLION LIMITED | I24: AWS (Amazon Web Service) | K24: 782264075267 | M24: Root Login : admin@goldwellcap.com | Q24: 43969 | T24: CL544184 | U24: 121718/1-2 | V24: 102375 | Y24: Csutomer email: sunnymak@firstbullion.com [14-May-2020] Pending for ingram reply email [15-May-2020] Invitation sent to customer. Pending for accept [20-Mar-2020] ASM reissue for 5 x separated orders [4-Jan-2020] cxl order
A25: Cancelled | D25: Sunny Mak | E25: 21146105/ 92538264 | G25: FIRST ASIA MERCHANTS BULLION LIMITED | H25: =IFERROR(VLOOKUP(G25, Sheet2!$A:$B, 2, FALSE), A25) -> FIRST ASIA MERCHANTS BULLION LIMITED | I25: AWS (Amazon Web Service) | K25: 477519521139 | M25: Root Login : admin@firstfx.bz | Q25: 43969 | T25: CL545380 | U25: 121718/3-4 | V25: 102386 | Y25: [15-May-2020] Invitation sent to customer. Pending for accept [4-Jan-2020] cxl order
A26: Cancelled | D26: Sunny Mak | E26: 21146105/ 92538264 | G26: FIRST ASIA MERCHANTS BULLION LIMITED | H26: =IFERROR(VLOOKUP(G26, Sheet2!$A:$B, 2, FALSE), A26) -> FIRST ASIA MERCHANTS BULLION LIMITED | I26: AWS (Amazon Web Service) | K26: 721697153034 | M26: Root Login : admin1@firstbullion.com | Q26: 43969 | T26: CL545401 | U26: 121718/5-6 | V26: 102385 | Y26: [15-May-2020] Invitation sent to customer. Pending for accept [4-Jan-2020] cxl order
A27: Cancelled | D27: Sunny Mak | E27: 21146105/ 92538264 | G27: FIRST ASIA MERCHANTS BULLION LIMITED | H27: =IFERROR(VLOOKUP(G27, Sheet2!$A:$B, 2, FALSE), A27) -> FIRST ASIA MERCHANTS BULLION LIMITED | I27: AWS (Amazon Web Service) | K27: 403046075669 | M27: Root Login : admin1@goldenfxlink.com | Q27: 43969 | T27: CL545407 | U27: 121718/7-8 | V27: 102384 | Y27: [15-May-2020] Invitation sent to customer. Pending for accept [4-Jan-2020] cxl order
A28: Cancelled | D28: Sunny Mak | E28: 21146105/ 92538264 | G28: FIRST ASIA MERCHANTS BULLION LIMITED | H28: =IFERROR(VLOOKUP(G28, Sheet2!$A:$B, 2, FALSE), A28) -> FIRST ASIA MERCHANTS BULLION LIMITED | I28: AWS (Amazon Web Service) | K28: 613594070113 | M28: Root Login : admin@goldenfxvip.com | Q28: 43969 | T28: CL545411 | U28: 121718/9-10 | V28: 102383 | Y28: [15-May-2020] Invitation sent to customer. Pending for accept [4-Jan-2020] cxl order
A29: Completed | D29: HENRY IP | E29: 68226722 | G29: EMPERIO GOLD AND SILVER COINS (HK) LTD | H29: =IFERROR(VLOOKUP(G29, Sheet2!$A:$B, 2, FALSE), A29) -> EMPERIO GOLD AND SILVER COINS (HK) LTD | I29: AWS (Amazon Web Service) | K29: 641582690281 | M29: Root Login: it@emperio-group.com | Q29: 44097 | S29: 44091 | T29: CL548980 | U29: 318774/1-2 | V29: 102458 | Y29: EMAIL : HENRYIP@EMPERIO-GROUP.COM [16-Sep-2020] Submitted request to Ingram [17-Sep-2020] Cus accepted the request. Completed in CxS. Pending usage consumption for cloudcheckr setup [18-Jan-2021] Welcome letter sent | Z29: N
A30: Completed | D30: Andy Ho | E30: 96121651 | G30: ULTRON TECHNOLOGY SG PTE. LIMITED (Pervious Name : EASY GREAT TECHNOLOGY LIMITED) | H30: =IFERROR(VLOOKUP(G30, Sheet2!$A:$B, 2, FALSE), A30) -> ULTRON TECHNOLOGY SG PTE. LIMITED | I30: Alibaba Cloud | K30: 5835359715465752 | M30: Alibaba Admin : dns.admin@ecg-tech.com Company Name chang to "ULTRON TECHNOLOGY SG PTE. LIMITED" | P30: Alibaba Cloud Admin Login Email: 5129223590947611 (hostmaster@naverhk.com ) | Q30: 43959 | S30: 43964 | T30: CL542163 | U30: 081569/1-2 | V30: 102364 | Y30: Alibaba Cloud Account ID : 5835359715465752 (dns.admin@ecg-tech.com ) Alibaba Cloud Admin Login Email: 5129223590947611 (hostmaster@naverhk.com ) [11-May-2020] Pending for Alibaba to proceed. Takes 1-2 days [13-May-2020] Completed on 13-May-2020. [18-May-2020] Completed in CxS with completion date on 13-May. [28-Apr-2021] Migration request from Zens to B-Data by Thomas [2-Jun-2021] Migration done on 2-Jun forUID. 5835359715465752 (dns.admin@ecg-tech.com )
A31: Cancelled | D31: Andy Ho | E31: 96121651 | F31: customer email: andy.ho@ecg-tech.com | G31: ULTRON TECHNOLOGY SG PTE. LIMITED (Pervious Name : EASY GREAT TECHNOLOGY LIMITED) | H31: =IFERROR(VLOOKUP(G31, Sheet2!$A:$B, 2, FALSE), A31) -> ULTRON TECHNOLOGY SG PTE. LIMITED | I31: AWS (Amazon Web Service) | K31: 787762068875 | M31: Root Login : sysadmin@889bcd.com | Q31: 43958 | T31: CL543185 | U31: 684634/1-2 | V31: 102366 | Y31: customer email: andy.ho@ecg-tech.com Will proceed another acc first [28-Jan-2021] sent email to salesruby for status update. [17-Feb-2021] Order cxl.
A32: Completed | D32: Andy Ho | E32: 96121651 | F32: customer email: andy.ho@ecg-tech.com | G32: ULTRON TECHNOLOGY SG PTE. LIMITED (Pervious Name : EASY GREAT TECHNOLOGY LIMITED) | H32: =IFERROR(VLOOKUP(G32, Sheet2!$A:$B, 2, FALSE), A32) -> ULTRON TECHNOLOGY SG PTE. LIMITED | I32: AWS (Amazon Web Service) | K32: 590419121026 | L32: Ilovecoin (Easy Great) | M32: Root Login : hostmaster@ilovecoin.com Company Name chang to "ULTRON TECHNOLOGY SG PTE. LIMITED" | Q32: 43972 | S32: 43969 | T32: CL544252 | U32: 475806/1-2 | V32: 102376 | Y32: customer email: andy.ho@ecg-tech.com [14-May-2020] Pending for ingram reply email [15-May-2020] Invitation sent to customer. Pending for accept [18-May-2020] Customer accepted and added customer to Cloud Checkr ilovecoin ( Easy Great). Completed in CxS. [8-Aug-2022] Sent request to martin to removed cus from HKT account. Done
A33: Completed | D33: Andy Ho | E33: 96121651 | G33: ULTRON TECHNOLOGY SG PTE. LIMITED (Pervious Name : EASY GREAT TECHNOLOGY LIMITED) | H33: =IFERROR(VLOOKUP(G33, Sheet2!$A:$B, 2, FALSE), A33) -> ULTRON TECHNOLOGY SG PTE. LIMITED | I33: Alibaba Cloud | K33: Alibaba Cloud Account ID : 5129223590947611 | M33: Alikbaba Admin : hostmaster@naverhk.com Company Name chang to "ULTRON TECHNOLOGY SG PTE. LIMITED" | Q33: 43972 | S33: 43970 | T33: CL544189 | U33: 057011/1-2 | V33: 102374 | Y33: Alibaba Cloud Account ID : 5129223590947611 [19-May-2020] Ann updated that Linked to HKT on 12-May (hostmaster@naverhk.com).Completed in CxS with completiondate on 19-May-2020 ( can't put remark )
A34: Completed | D34: Andy Ho | E34: 96121651 | F34: customer email: andy.ho@ecg-tech.com | G34: ULTRON TECHNOLOGY SG PTE. LIMITED (Pervious Name : EASY GREAT TECHNOLOGY LIMITED) | H34: =IFERROR(VLOOKUP(G34, Sheet2!$A:$B, 2, FALSE), A34) -> ULTRON TECHNOLOGY SG PTE. LIMITED | I34: AWS (Amazon Web Service) | K34: 484603839389 | L34: Hbeemail (Easy Great) | M34: Root Login : pmjp@hbeemail.com Company Name chang to "ULTRON TECHNOLOGY SG PTE. LIMITED" | Q34: 43972 | S34: 43971 | T34: CL544208 | U34: 42533/1-2 | V34: 102377 | Y34: customer email: andy.ho@ecg-tech.com [13-May] submitted to ingram. Pending for reply [15-May-2020] Invitation sent to customer. Pending for accept [20-May-2020] Add customer in Cloud Checkr Hbeemail (Easy Great). Completed in CxS. [8-Aug-2022] Sent request to martin to removed cus from HKT account. Done
A35: Completed | D35: Mr. Jacky Hui | E35: 96742005 | F35: Contact Person: jacky.hui@ddaapp.com | G35: DDAAPP Studio | H35: =IFERROR(VLOOKUP(G35, Sheet2!$A:$B, 2, FALSE), A35) -> DDAAPP LIMITED | I35: AWS (Amazon Web Service) | K35: 889849555457 | M35: Login account : enterprise@ddaapp.com Password : 1u3oc7fibx | P35: Root Login : enterprise@ddaapp.com | Q35: 43808 | S35: 43840 | T35: CL548273 | U35: 821828/1-2 | V35: 102250 | Y35: AWS Account ID: 889849555457 Root Login : enterprise@ddaapp.com Contact Person: jacky.hui@ddaapp.com [4-Jun-2020] moved to Ingram Micro on 1-Jun and added into HKT family on 4-Jun.
A36: Completed | D36: Daniel Yeung | E36: 31016889 / 98633579 | F36: Email : daniel.cw.yeung@cityline.com.hk | G36: CITYLINE (HONG KONG) LIMITED | H36: =IFERROR(VLOOKUP(G36, Sheet2!$A:$B, 2, FALSE), A36) -> CITYLINE (HONG KONG) LIMITED | I36: AWS (Amazon Web Service) | K36: 5943307259 | M36: Root Login : disney@cityline.com.hk | O36: Address: 23/F, Legend Tower, 7 Shing Yip Street, Kwung Tong | Q36: 44111 | S36: 44147 | T36: CL549093 | U36: 592730/1-2 | V36: 102468 | Y36: Address: 23/F, Legend Tower, 7 Shing Yip Street, Kwung Tong Email : daniel.cw.yeung@cityline.com.hk [5-Oct-2020] AWS root emil. Penidng for sales to provide [21-Oct-2020] AMSAMMI provbide root login of AWS ID: 697887384373. Pending for the 2nd root login. [6-Nov-2020] Submit the requets for 005943307259 first as per AM Sammi request and pending for ingram linkup. [10-Nov-2020] account linked. Pending for cus to accept invitation. [12-Nov-2020] AM Sammi updated that cus has accepted the invitation of AWS ID: 005943307259. Pendng for the 2nd root login for linkage [13-Nov-20] welcome letter sent ( AWS ID: 005943307259 ) [14-Jan-2020] The pending acc(AWS ID: 697887384373) will be split into another order. Completed (AWS ID: 005943307259) order in System [5-Jan-2023] Rec'd email from Product Thomas for the termination of this account. Remove rights in Cloud Checkr and Martin will unlink the account in AWS organization. Termination order will be issued later with SRD on 6-Feb-2023. [18-Dec-2023] Confirm by Katie Chai CL549093 is no more usage since 1 Mar 2023. Completed order in CxS | Z36: N
A37: Completed | D37: Jack Leung | E37: 2610 8769 / 96023323 | F37: Customer Email: jackleung@chowtaifook.com | G37: CHOW TAI FOOK JEWELLERY CO LTD | H37: =IFERROR(VLOOKUP(G37, Sheet2!$A:$B, 2, FALSE), A37) -> CHOW TAI FOOK JEWELLERY CO LTD | I37: AWS (Amazon Web Service) | J37: 726125834629 | K37: 275030332822 | M37: Root Login : aws@chowtaifook.com | Q37: 44034 | S37: 44034 | T37: CL557719 | U37: 578448/1-2 | V37: 102416 | Y37: Customer Email: jackleung@chowtaifook.com [22-Jul-20] Submitted request to Ingram. Customer accepted invitation [27-Jul-20] CloudCheckr setup completed. Welcome letter sent. Completed in Cxs with completion date on 22-Jul-2020. [18-Dec-2023] Confirm by Lok PS Job has done. Close CxS no.: 829459/1 | Z37: N | AA37: N
A38: Completed | D38: Jack Leung | E38: 2610 8769 / 96023323 | G38: CHOW TAI FOOK JEWELLERY CO LTD (vcchoi) | H38: =IFERROR(VLOOKUP(G38, Sheet2!$A:$B, 2, FALSE), A38) -> CHOW TAI FOOK JEWELLERY CO LTD | I38: AWS (Amazon Web Service) | J38: 726125834629 | K38: 757895108869 | M38: Root Login : vcchoi@chowtaifook.com | O38: Address: 25/F , World Peace centre, 41-55 Wo Tong Tsui St, Kwai Chung, NT | Q38: 44113 | S38: 44113 | T38: CL547335 | U38: 543588/1-2 | V38: 102470 | Y38: Remark: PS job ( pls pass to Johnny Team Address: 25/F , World Peace centre, 41-55 Wo Tong Tsui St, Kwai Chung, NT [6-Oct-2020] Pending for Cus to join. [9-Oct-2020] Ingram resent invitation as the invitation got some issue showing invitation cxl. [12-Oct-2020] Consultant Tony confirmed invitation accept done. Completed order in CxS with completion date on 9-Oct. Inform AM to issue PS job order. Pending for usage consumption for cloudchecr setup and PS job order [16-Oct-2020] Informed by Thomas that there are two PS job ( TM1 + Lamdba ).Thomas to clarify with ASM [29-Oct-2020] Setup CloudCheckr Acc and welcome letter sent [18-Dec-2023] Confirm by Lok PS Job has done. Completed order in CxS | Z38: N
A39: Completed | D39: Croven Phang | E39: 63365303 | F39: Customer Email: croven.phang@yahoo.com.sg | G39: Celestial Key Ventures Limited | H39: =IFERROR(VLOOKUP(G39, Sheet2!$A:$B, 2, FALSE), A39) -> Celestial Key Ventures Limited | I39: Microsoft Azure | M39: CSP Domain: ckvl.onmicrosoft.com | Q39: 43993 | S39: 43990 | T39: CL547398 | U39: RN498425/1-2 | V39: 102400 | Y39: Customer Email: croven.phang@yahoo.com.sg [9-Jun-2020] License has been assigned. Completed order in CxS with completion date on 8-Jun,
A40: Completed | D40: Roland Wong(GLP) | E40: +853 8982 0209/+853 6333 0729 | G40: CAM 8 PCCW (Macau) Ltd c/o SJM | H40: =IFERROR(VLOOKUP(G40, Sheet2!$A:$B, 2, FALSE), A40) -> CAM 8 PCCW (Macau) Ltd c/o SJM | I40: Alibaba Cloud | K40: Alibaba Cloud Account ID :5913782617694380 | M40: Alibaba Admin : itsoc@macausjm-glp.com | Q40: 43887 | S40: 43894 | T40: CL545947 | U40: 050255/1-2 | V40: 102330 | Y40: Alibaba Cloud Admin Login Email: itsoc@macausjm-glp.com [2-Mar-2020] Backdate order. Ann has provisioned the tenant to customer wit SRD on 26-Feb-2020. [4-Mar-2020] Order completed in CxS with completion date marked on 26-Feb-2020. [28-Apr-2021] Migration request from Zens to B-Data by Thomas
...

Sheet Sheet2
A1: Company Name | B1: Standardized
A2: WING FUNG REALTY INVESTMENT LIMITED | B2: WING FUNG REALTY INVESTMENT LIMITED
A3: WING FUNG PRECIOUS METALS LIMITED | B3: WING FUNG PRECIOUS METALS LIMITED
A4: WING FUNG FUTURES LIMITED | B4: WING FUNG FUTURES LIMITED
A5: WING FUNG BULLION INVESTMENT LIMITED | B5: WING FUNG BULLION INVESTMENT LIMITED
A6: UMADX ONLINE (MALAYSIA) SDN. BHD | B6: UMADX ONLINE (MALAYSIA) SDN. BHD
A7: TYSAN MANAGEMENT LIMITED | B7: TYSAN MANAGEMENT LIMITED
A8: TRAVELSKY TECHNOLOGY (HONGKONG) LTD. | B8: TRAVELSKY TECHNOLOGY (HONGKONG) LTD.
A9: Techtronic Industries Co. Ltd | B9: Techtronic Industries Co. Ltd
A10: SOFI SECURITIES LIMITED (SOFI SERVICES ( HONG KONG ) LTD) | B10: SOFI SECURITIES LIMITED (SOFI SERVICES ( HONG KONG ) LTD)
A11: PROFIT CHART DEVELOPMENT LIMITED | B11: PROFIT CHART DEVELOPMENT LIMITED
A12: ORANGE DATA LIMITED (Chnaged ASCENTAS CAPITAL MANAGEMENT LIMITED) | B12: ASCENTAS CAPITAL MANAGEMENT LIMITED
... A209: CAM 8_HKT GenAI Demo Platform | B209: CAM 8_HKT GenAI Demo Platform
